Traceback (most recent call last):
  File "C:\Users\User\AppData\Roaming\Python\Python39\site-packages\urllib3\connection.py", line 140, in _new_conn
    conn = connection.create_connection(
  File "C:\Users\User\AppData\Roaming\Python\Python39\site-packages\urllib3\util\connection.py", line 83, in create_connection
    raise err
  File "C:\Users\User\AppData\Roaming\Python\Python39\site-packages\urllib3\util\connection.py", line 73, in create_connection
    sock.connect(sa)
TimeoutError: [WinError 10060] A connection attempt failed because the connected party did not properly respond after a period of time, or established connection failed because connected host has failed to respond

During handling of the above exception, another exception occurred:        

Traceback (most recent call last):
  File "C:\Users\User\AppData\Roaming\Python\Python39\site-packages\urllib3\connectionpool.py", line 598, in urlopen
    httplib_response = self._make_request(conn, method, url,
  File "C:\Users\User\AppData\Roaming\Python\Python39\site-packages\urllib3\connectionpool.py", line 357, in _make_request
    conn.request(method, url, **httplib_request_kw)
  File "C:\Program Files\Python39\lib\http\client.py", line 1257, in request
    self._send_request(method, url, body, headers, encode_chunked)
  File "C:\Program Files\Python39\lib\http\client.py", line 1303, in _send_request
    self.endheaders(body, encode_chunked=encode_chunked)
  File "C:\Program Files\Python39\lib\http\client.py", line 1252, in endheaders
    self._send_output(message_body, encode_chunked=encode_chunked)
  File "C:\Program Files\Python39\lib\http\client.py", line 1012, in _send_output
    self.send(msg)
  File "C:\Program Files\Python39\lib\http\client.py", line 952, in send   
    self.connect()
  File "C:\Users\User\AppData\Roaming\Python\Python39\site-packages\urllib3\connection.py", line 166, in connect
    conn = self._new_conn()
  File "C:\Users\User\AppData\Roaming\Python\Python39\site-packages\urllib3\connection.py", line 149, in _new_conn
    raise NewConnectionError(
urllib3.exceptions.NewConnectionError: <urllib3.connection.HTTPConnection object at 0x00000237546C0550>: Failed to establish a new connection: [WinError 10060] A connection attempt failed because the connected party did not properly respond after a period of time, or established connection failed because connected host has failed to respond

During handling of the above exception, another exception occurred:        

Traceback (most recent call last):
  File "C:\Users\User\AppData\Roaming\Python\Python39\site-packages\requests\adapters.py", line 439, in send
    resp = conn.urlopen(
  File "C:\Users\User\AppData\Roaming\Python\Python39\site-packages\urllib3\connectionpool.py", line 638, in urlopen
    retries = retries.increment(method, url, error=e, _pool=self,
  File "C:\Users\User\AppData\Roaming\Python\Python39\site-packages\urllib3\util\retry.py", line 388, in increment
    raise MaxRetryError(_pool, url, error or ResponseError(cause))
urllib3.exceptions.MaxRetryError: HTTPConnectionPool(host='172.31.6.64', port=8090): Max retries exceeded with url: /get_all_process_stations_ui/ (Caused by NewConnectionError('<urllib3.connection.HTTPConnection object at 0x00000237546C0550>: Failed to establish a new connection: [WinError 10060] A 
connection attempt failed because the connected party did not properly respond after a period of time, or established connection failed because connected host has failed to respond'))

During handling of the above exception, another exception occurred:        

Traceback (most recent call last):
  File "c:\Users\User\Desktop\New folder (2)\Dashboard-CTH\app.py", line 23, in <module>
    response = requests.get(url)
  File "C:\Users\User\AppData\Roaming\Python\Python39\site-packages\requests\api.py", line 75, in get
    return request('get', url, params=params, **kwargs)
  File "C:\Users\User\AppData\Roaming\Python\Python39\site-packages\requests\api.py", line 61, in request
    return session.request(method=method, url=url, **kwargs)
  File "C:\Users\User\AppData\Roaming\Python\Python39\site-packages\requests\sessions.py", line 542, in request
    resp = self.send(prep, **send_kwargs)
  File "C:\Users\User\AppData\Roaming\Python\Python39\site-packages\requests\sessions.py", line 655, in send
    r = adapter.send(request, **kwargs)
  File "C:\Users\User\AppData\Roaming\Python\Python39\site-packages\requests\adapters.py", line 516, in send
    raise ConnectionError(e, request=request)
requests.exceptions.ConnectionError: HTTPConnectionPool(host='172.31.6.64', port=8090): Max retries exceeded with url: /get_all_process_stations_ui/ (Caused by NewConnectionError('<urllib3.connection.HTTPConnection object at 
0x00000237546C0550>: Failed to establish a new connection: [WinError 10060] A connection attempt failed because the connected party did not properly respond after a period of time, or established connection failed because connected host has failed to respond'))